<?xml version="1.0"?>
<!--
  2WD Patrol Robot URDF Model
  Author: Sokratis Dimitriadis
  Description: Simplified URDF of 2-wheeled mobile robot for testing in simulation (RViz or Gazebo).
  Version: 0.2
-->
  
<!--Initialise our robot structure with its name-->
<robot name="2wd_patrol_bot">

  <!--Different colours setups with codes-->
  <material name="bluelike">
    <color rgba="0.337 0.357 0.91 0.8" />
  </material>

  <material name="cypressgreen">
    <color rgba="0.29 0.929 0.765 0.8" />
  </material>

  <material name="green">
    <color rgba="0 1 0 1" />
  </material>

  <material name="blue">
    <color rgba="0 0 1 1" />
  </material>

  <material name="red">
    <color rgba="1 0 0 1" />
  </material>

  <material name="orange">
    <color rgba="0.949 0.565 0.094 1" />
  </material>


  <!--LINKS-->
  <!--Base link of the robot-First rigid part to start from-->
  <link name="base_link">

    <!--Visual of the robot to create its geometry, colour, origin, etc-->
    <visual>
      <geometry>
        <box size="0.6 0.4 0.2" />
      </geometry>
      <material name="orange" />
      <origin xyz="0 0 0.1" rpy="0 0 0" /> <!--Set the origin to be half its height so it can sit on the ground-->
    </visual>

    <!--Collision geometry-->
    <collision>
      <geometry>
        <box size="0.6 0.4 0.2" />
      </geometry>
    </collision>

    <!--Inertia description-->
    <inertial>
      <mass value="6.0"/>
      <origin xyz="0 0 0" rpy="0 0 0"/>
      <inertia ixx="0.04" iyy="0.04" izz="0.04" ixy="0.0" ixz="0.0" iyz="0.0"/>
    </inertial>

  </link>

  <!--Empty link for the robot footprint-->
  <link name ="base_footprint"/>

  <!-- WHEELS -->
  <!--Making the wheels for the robot-->
  <link name="left_wheel">
    <visual>
      <geometry>
        <cylinder radius="0.1" length="0.05" />
      </geometry>
      <material name="cypressgreen" />
      <origin xyz="0 0 0" rpy="1.570 0 0" />
    </visual>
  </link>

  <link name="right_wheel">
    <visual>
      <geometry>
        <cylinder radius="0.1" length="0.05" />
      </geometry>
      <material name="cypressgreen" />
      <origin xyz="0 0 0" rpy="1.570 0 0" />
    </visual>
  </link>

  <!--Making the caster wheel (sphere) for the robot to stand-->
  <link name="caster_wheel">
    <visual>
      <geometry>
        <sphere radius="0.05" />
      </geometry>
      <material name="blue" />
      <origin xyz="0 0 0" rpy="0 0 0" />
    </visual>
  </link>

  <!-- Add element on-board stereoscopic camera etc -->
  <link name="addon_base">
    <visual>
      <geometry>
        <cylinder radius="0.05" length="0.1" />
      </geometry>
      <material name="red" />
      <origin xyz="0 0 0.05" rpy="0 0 0" />
    </visual>
  </link>

  <!--We need joints for parent-child relationship of links-->
  <!--JOINTS-->
  <joint name="base_joint" type="fixed">
    <parent link="base_footprint" />
    <child link="base_link" />
    <origin xyz="0 0 0.1" rpy="0 0 0" />
  </joint>

  <joint name="left_wheel_joint" type="continuous"> <!-- Type is continuous for 360 revolution -->
    <parent link="base_link" />
    <child link="left_wheel" />
    <origin xyz="-0.15 -0.225 0" rpy="0 0 0" /> <!--About
    a quarter of the robot's length for wheel position on x, half its width plus half the width of
    the wheel to be on the edge of it on y-->
    <axis xyz="0 1 0" /> <!-- Axis required for rotation -->
  </joint>

  <joint name="right_wheel_joint" type="continuous">
    <parent link="base_link" />
    <child link="right_wheel" />
    <origin xyz="-0.15 0.225 0" rpy="0 0 0" />
    <axis xyz="0 1 0" />
  </joint>

  <joint name="caster_wheel_joint" type="fixed">
    <parent link="base_link" />
    <child link="caster_wheel" />
    <origin xyz="0.15 0 -0.05" rpy="0 0 0" />
  </joint>

  <joint name="addon_base_joint" type="revolute"> <!-- Type revolute needs limits to work (see below) -->
    <parent link="base_link" />
    <child link="addon_base" />
    <origin xyz="0 0 0.2" rpy="0 0 0" />
    <axis xyz="0 0 1" /> <!-- Axis required for rotation -->
    <limit lower="-1.57" upper="1.57" velocity="10" effort="10" />
  </joint>

  <!-- TRANSMISSIONS -->
  <transmission name="left_wheel_trans">
    <type>transmission_interface/SimpleTransmission</type>
    <joint name="left_wheel_joint">
      <hardwareInterface>hardware_interface/VelocityJointInterface</hardwareInterface>
    </joint>
    <actuator name="left_motor">
      <mechanicalReduction>1</mechanicalReduction>
    </actuator>
  </transmission>

  <transmission name="right_wheel_trans">
    <type>transmission_interface/SimpleTransmission</type>
    <joint name="right_wheel_joint">
      <hardwareInterface>hardware_interface/VelocityJointInterface</hardwareInterface>
    </joint>
    <actuator name="right_motor">
      <mechanicalReduction>1</mechanicalReduction>
    </actuator>
  </transmission>

  <!-- GAZEBO PLUGIN -->
  <gazebo>
    <plugin name="diff_drive" filename="libgazebo_ros_diff_drive.so">
      <left_wheel>left_wheel_joint</left_wheel>
      <right_wheel>right_wheel_joint</right_wheel>
      <updateRate>50</updateRate>
      <robotBaseFrame>base_link</robotBaseFrame>
      <publishWheelTF>true</publishWheelTF>
      <publishTf>1</publishTf>
      <publishOdom>true</publishOdom>
      <odometryFrame>odom</odometryFrame>
      <commandTopic>/cmd_vel</commandTopic>
      <odometryTopic>/odom</odometryTopic>
    </plugin>
  </gazebo>


</robot>